<?xml version="1.0"?>
<robot name="turret_bot">
    <link name="base">
        <visual>
            <geometry>
                <mesh filename="package://turret_bot/meshes/base.stl" scale="1 1 1"/>
            </geometry> 
            <material name="red">
                <color rgba="0.8 0 0 1"/>    
            </material>  
        </visual>
        <collision>
            <geometry>
                <mesh filename="package://turret_bot/meshes/base.stl" scale="1 1 1"/>
            </geometry> 
        </collision>
        <inertial>
            <origin xyz="0 0.5 0" rpy="0 0 0"/>
            <mass value="16"/>
            <inertia ixx="1.376" ixy="0" ixz="0" iyy="0.317" iyz="0" izz="1.607"/>
        </inertial>
    </link>
    <link name="slider">
        <visual>
            <geometry>
                <mesh filename="package://turret_bot/meshes/slider.stl" scale="1 1 1"/>
            </geometry>    
            <material name = "green">
                <color rgba="0 0.8 0 1"/>    
            </material>  
        </visual>
        <collision>
            <geometry>
                <mesh filename="package://turret_bot/meshes/slider.stl" scale="1 1 1"/>
            </geometry>
        </collision>
        <inertial>
            <origin xyz="0 0.05 0.165" rpy="0.0 0.0 0.0"/>
            <mass value="9.8075"/>
            <inertia ixx="0.15206" ixy="0.0" ixz="0.0" iyy="0.2293" iyz="0.0" izz="0.09238"/>
        </inertial>
    </link>
    <link name="rotor">
        <visual>
            <geometry>
                <mesh filename="package://turret_bot/meshes/rotor.stl" scale="1 1 1"/>
            </geometry>
            <material name = "blue">
                <color rgba="0 0 0.8 1"/>    
            </material>      
        </visual>
        <collision>
            <geometry>
                <mesh filename="package://turret_bot/meshes/rotor.stl" scale="1 1 1"/>
            </geometry>
        </collision>
        <inertial>
            <origin xyz="0.13 0 0.03" rpy="0.0 0.0 0.0"/>
            <mass value="2.114"/>
            <inertia ixx="0.00215" ixy="0.0" ixz="0.0" iyy="0.02074" iyz="0.0" izz="0.02201"/>
        </inertial>
        
    </link>

    <joint name="j1" type="prismatic">
        <origin xyz="0 0 0" rpy="0 0 0"/>
        <axis xyz="0 1 0"/>
        <limit lower="0" upper="1" effort="1000" velocity="50"/>
        <parent link="base"/>
        <child link="slider"/>
        <dynamics damping="0.001" friction="0.001"/>
    </joint>
    <joint name="j2" type="revolute">
        <origin xyz="0 0.05 0.475" rpy="0.0 0.0 0.0"/>
        <axis xyz="0 0 1"/>
        <limit lower="-3.14" upper="3.14" effort="1000" velocity="50"/>
        <parent link="slider"/>
        <child link="rotor"/>
        <dynamics damping="0.001" friction="0.001"/>
    </joint>
    <gazebo reference="base">
        <material>Gazebo/Green</material>
    </gazebo>
    <gazebo reference="slider">
        <material>Gazebo/Red</material>
    </gazebo>
    <gazebo reference="rotor">
        <material>Gazebo/Blue</material>
    </gazebo>

    <transmission name = "t1">
        <type>transmission_interface/SimpleTransmission</type>
        <joint name="j1">
            <hardwareInterface>hardware_interface/PositionJointInterface</hardwareInterface>
        </joint>
        <actuator name="a1">
            <mechanicalReduction>1</mechanicalReduction>
        </actuator>
    </transmission>
    <transmission name = "t2">
        <type>transmission_interface/SimpleTransmission</type>
        <joint name="j2">
            <hardwareInterface>hardware_interface/PositionJointInterface</hardwareInterface>
        </joint>
        <actuator name="a2">
            <mechanicalReduction>1</mechanicalReduction>
        </actuator>
    </transmission>
    <gazebo>
        <plugin name = "gazebo_ros_control" filename="libgazebo_ros_control.so"/>
    </gazebo>
</robot>